Workbook
Name Slicer_Chapter: #N/A
Name Slicer_Chapter1: #N/A
Name Slicer_Chapter11: #N/A
Name Slicer_Chapter12: #N/A
Name Slicer_Chapter2: #N/A
Name Slicer_Chapter3: #N/A

Sheet PVT
B10: InReport | C10: TRUE | H10: InReport | I10: TRUE
U11: Total Portfolio
B12: Closed Positions | C12: Max of ToM | D12: Entry Value | E12: Exit Value | F12: Realized Gains | H12: Open Positions | I12: Holding Period (Mon) | J12: Entry Value USD | K12: Market Value USD | L12: Unrealized Gains | M12: Unrealized Gains % | O12: Row Labels | P12: Value | R12: Free Cash | S12: ='CLOSED POSITION HISTORY'!$J$9 -> 85.05 | U12: Portfolio Summary | V12: USD | W12: % Of Invested
B13: Stock Holding | C13: 10.102225 | D13: 843.87 | E13: 915.69 | F13: 51.7 | H13: Consumer Defensive | I13: 10.880315 | J13: 407.81 | K13: 409.92 | L13: 2.11 | M13: 0.0051739781 | O13: DIVIDENT | P13: 14.79 | R13: INV CAPITAL | S13: =MIN(O34:O246) -> -1560.49 | U13: Invested Capital | V13: =V14-V15 -> 1490.49 | W13: =V13/$V$13 -> 1
B14: Financial Services | C14: 8.9815609 | D14: 127.47 | E14: 148.9 | F14: 21.43 | H14: ETF | I14: 10.164654 | J14: 358.7 | K14: 364.3 | L14: 5.6 | M14: 0.015611932 | O14: commission | P14: 0 | U14: Active Investment Value | V14: =GETPIVOTDATA("Market Value USD",$H$12) -> 1557.83 | W14: =V14/$V$13 -> 1.0451798
B15: Energy & Utilities | C15: 4.1938561 | D15: 145.91 | E15: 161.8 | F15: 15.88 | H15: Energy & Utilities | I15: 9.2089968 | J15: 303.27 | K15: 312.25 | L15: 8.98 | M15: 0.029610578 | O15: Sec Fee | P15: -0.01 | U15: Unrealized Gains | V15: =GETPIVOTDATA("Unrealized Gains",$H$12) -> 67.34 | W15: =V15/$V$13 -> 0.045179773
B16: ETF | C16: 5.0261935 | D16: 92.47 | E16: 99.68 | F16: 7.21 | H16: Technology | I16: 10.10045 | J16: 233.35 | K16: 256.74 | L16: 23.39 | M16: 0.1002357 | O16: Withholding Tax | P16: -3.93 | U16: Realized Gains | V16: =GETPIVOTDATA("Realized Gains",$B$12,"Type","Stock Holding") -> 51.7 | W16: =V16/$V$13 -> 0.03468658
B17: Technology | C17: 10.102225 | D17: 404.77 | E17: 408.2 | F17: 3.43 | H17: Financial Services | I17: 5.5405044 | J17: 187.32 | K17: 214.58 | L17: 27.26 | M17: 0.14552637 | O17: Grand Total | P17: 10.85 | U17: Dividends | V17: =GETPIVOTDATA("Amount",$O$12,"Type","DIVIDENT") -> 14.79 | W17: =V17/$V$13 -> 0.0099229113
B18: Consumer Cyclical | C18: 3.7753006 | D18: 33.95 | E18: 36.71 | F18: 2.76 | H18: ING | I18: 5.5405044 | J18: 65.64 | K18: 83.09 | L18: 17.45 | M18: 0.265844 | U18: Available Cash | V18: =S12 -> 85.05 | W18: =V18/$V$13 -> 0.057061772
B19: Consumer Defensive | C19: 9.2747881 | D19: 39.3 | E19: 60.4 | F19: 0.99 | H19: BCS | I19: 0.91411083 | J19: 40 | K19: 44.28 | L19: 4.28 | M19: 0.107 | O19: Row Labels | P19: Value | U19: Total Cash Returns | V19: =V17+V16 -> 66.49 | W19: =V19/$V$13 -> 0.044609491
B20: Grand Total | C20: 10.102225 | D20: 843.87 | E20: 915.69 | F20: 51.7 | H20: MA | I20: 4.8142117 | J20: 30.46 | K20: 34.59 | L20: 4.13 | M20: 0.13558766 | O20: Grand Total | U20: Tax & Fees | V20: =IFERROR(GETPIVOTDATA("Amount",$O$12,"Type","commission"),0)+IFERROR(GETPIVOTDATA("Amount",$O$12,"Type","Sec Fee"),0)+IFERROR(GETPIVOTDATA("Amount",$O$12,"Type","Withholding Tax"),0) -> -3.94 | W20: =V20/$V$13 -> -0.002643426
H21: BBVA.ES | I21: 0.23164507 | J21: 25 | K21: 25.62 | L21: 0.62 | M21: 0.0248 | U21: Total P&L | V21: =V20+V17+V16+V15 -> 129.89 | W21: =V21/$V$13 -> 0.087145838
H22: CIB | I22: 0.10119022 | J22: 19.99 | K22: 20.05 | L22: 0.06 | M22: 0.0030015008 | U22: FCF | V22: =V19+V20 -> 62.55 | W22: =V22/$V$13 -> 0.041966065
H23: V | I23: 1.3439307 | J23: 6.23 | K23: 6.95 | L23: 0.72 | M23: 0.11556982 | O23: Row Labels | P23: Value
H24: Consumer Cyclical | I24: 4.8142337 | J24: 0.04 | K24: 0.04 | L24: 0 | M24: 0 | O24: Stock sale | P24: 823.62 | U24: Portfolio Metrics
H25: Grand Total | I25: 10.880315 | J25: 1490.49 | K25: 1557.83 | L25: 67.34 | M25: 0.045179773 | O25: Stock purchase | P25: -2314.1 | U25: Holding Period (Months) | V25: =MAX(GETPIVOTDATA("Holding Period (Mon)",$H$12),GETPIVOTDATA("Max of ToM",$B$12,"Type","Stock Holding")) -> 10.880315
O26: Grand Total | P26: -1490.48 | U26: Overall Return % | V26: =W21 -> 0.087145838
U27: Avg Monthly Return % | V27: =V26/V25 -> 0.0080094959
U28: CAGR % | V28: =((V13+V21)/V13)^(12/V25)-1 -> 0.096534142
U29: Overal FCF % | V29: =W22 -> 0.041966065
U30: Avg FCF % | V30: =W22/V25 -> 0.0038570634
M31: Type | N31: (Multiple Items) | Q31: Type | R31: deposit | U31: FCF CAGR % | V31: =((V13+V22)/V13)^(12/V25)-1 -> 0.046383476
M33: Row Labels | N33: Value | O33: ACCUMULATIVE | Q33: Row Labels | R33: Value
M34: 45446.646 | N34: -20.57 | O34: =SUM($N$34:N34) -> -20.57
M35: 45446.894 | N35: -20 | O35: =SUM($N$34:N35) -> -40.57
M36: 45448.646 | N36: -20.25 | O36: =SUM($N$34:N36) -> -60.82
M37: 45449.868 | N37: -10 | O37: =SUM($N$34:N37) -> -70.82
M38: 45453.913 | N38: -10 | O38: =SUM($N$34:N38) -> -80.82
M39: 45460.646 | N39: -0.2 | O39: =SUM($N$34:N39) -> -81.02
M40: 45460.738 | N40: 0.2 | O40: =SUM($N$34:N40) -> -80.82
M41: 45460.885 | N41: -19.99 | O41: =SUM($N$34:N41) -> -100.81
M42: 45464.646 | N42: 40.25 | O42: =SUM($N$34:N42) -> -60.56
M43: 45464.661 | N43: -20 | O43: =SUM($N$34:N43) -> -80.56
M44: 45464.674 | N44: -20.36 | O44: =SUM($N$34:N44) -> -100.92
M45: 45476.646 | N45: -25.28 | O45: =SUM($N$34:N45) -> -126.2
... M211: 45792.761 | N211: -10 | O211: =SUM($N$34:N211) -> -1490.48
O212: =SUM($N$34:N212) -> -1490.48
O213: =SUM($N$34:N213) -> -1490.48
O214: =SUM($N$34:N214) -> -1490.48
O215: =SUM($N$34:N215) -> -1490.48
...

Sheet Summary
B5: Sum of Amount | C5: Column Labels | G5: Sum of Amount | H5: Column Labels
B6: Row Labels | C6: Net Income | D6: deposit | E6: Exposed Capital | G6: Row Labels | H6: Net Income | I6: Exposed Capital | J6: DATES | L6: DATES | M6: DEPOSIT BALANCE | N6: EXPOSE BALANCE | O6: Net Income | P6: Net Income % | Q6: Proyected Annualized Return % | R6: EXPOSITION %
B7: 2024-05-31 | D7: 100 | G7: 2024-06-03 | I7: -40.57 | J7: =VALUE(G7) -> 45446 | L7: =VALUE(B7) -> 45443 | M7: =SUM($D7:D$7) -> 100 | N7: =-SUMIFS(I:I,J:J,"<="&L7) -> 0 | O7: =SUMIFS(H:H,J:J,"<="&L7) -> 0 | P7: =IFERROR(O7/N7,0) -> 0 | Q7: =IFERROR((P7+1)^(12/((MAX($J$7:J7)-$J$7)/30.5))-1,0) -> 0 | R7: =N7/M7 -> 0
B8: 2024-06-03 | E8: -69.09 | G8: 2024-06-05 | I8: -20.25 | J8: =VALUE(G8) -> 45448 | L8: =VALUE(B8) -> 45446 | M8: =SUM($D$7:D8) -> 100 | N8: =-SUMIFS(I:I,J:J,"<="&L8) -> 40.57 | O8: =SUMIFS(H:H,J:J,"<="&L8) -> 0 | P8: =IFERROR(O8/N8,0) -> 0 | Q8: =IFERROR((P8+1)^(12/((MAX($J$7:J8)-$J$7)/30.5))-1,0) -> 0 | R8: =N8/M8 -> 0.4057 | AL8: =PVT!U11 -> Total Portfolio | AM8: =PVT!V11 -> 0 | AN8: =PVT!W11 -> 0
B9: 2024-06-05 | E9: -20.25 | G9: 2024-06-06 | I9: -10 | J9: =VALUE(G9) -> 45449 | L9: =VALUE(B9) -> 45448 | M9: =SUM($D$7:D9) -> 100 | N9: =-SUMIFS(I:I,J:J,"<="&L9) -> 60.82 | O9: =SUMIFS(H:H,J:J,"<="&L9) -> 0 | P9: =IFERROR(O9/N9,0) -> 0 | Q9: =IFERROR((P9+1)^(12/((MAX($J$7:J9)-$J$7)/30.5))-1,0) -> 0 | R9: =N9/M9 -> 0.6082 | AL9: Resumen de Portafolio | AM9: =PVT!V12 -> USD | AN9: =PVT!W12 -> % Of Invested
B10: 2024-06-06 | E10: -10 | G10: 2024-06-10 | I10: -10 | J10: =VALUE(G10) -> 45453 | L10: =VALUE(B10) -> 45449 | M10: =SUM($D$7:D10) -> 100 | N10: =-SUMIFS(I:I,J:J,"<="&L10) -> 70.82 | O10: =SUMIFS(H:H,J:J,"<="&L10) -> 0 | P10: =IFERROR(O10/N10,0) -> 0 | Q10: =IFERROR((P10+1)^(12/((MAX($J$7:J10)-$J$7)/30.5))-1,0) -> 0 | R10: =N10/M10 -> 0.7082 | AL10: Capital invertido | AM10: =PVT!V13 -> 1490.49 | AN10: =PVT!W13 -> 1
B11: 2024-06-10 | C11: -2.28 | E11: 5.15 | G11: 2024-06-17 | H11: 0 | I11: -19.99 | J11: =VALUE(G11) -> 45460 | L11: =VALUE(B11) -> 45453 | M11: =SUM($D$7:D11) -> 100 | N11: =-SUMIFS(I:I,J:J,"<="&L11) -> 80.82 | O11: =SUMIFS(H:H,J:J,"<="&L11) -> 0 | P11: =IFERROR(O11/N11,0) -> 0 | Q11: =IFERROR((P11+1)^(12/((MAX($J$7:J11)-$J$7)/30.5))-1,0) -> 0 | R11: =N11/M11 -> 0.8082 | AL11: Valor de Mercado | AM11: =PVT!V14 -> 1557.83 | AN11: =PVT!W14 -> 1.0451798
B12: 2024-06-15 | D12: 50 | G12: 2024-06-18 | H12: 0 | J12: =VALUE(G12) -> 45461 | L12: =VALUE(B12) -> 45458 | M12: =SUM($D$7:D12) -> 150 | N12: =-SUMIFS(I:I,J:J,"<="&L12) -> 80.82 | O12: =SUMIFS(H:H,J:J,"<="&L12) -> 0 | P12: =IFERROR(O12/N12,0) -> 0 | Q12: =IFERROR((P12+1)^(12/((MAX($J$7:J12)-$J$7)/30.5))-1,0) -> 0 | R12: =N12/M12 -> 0.5388 | AL12: Ganancias no realizadas | AM12: =PVT!V15 -> 67.34 | AN12: =PVT!W15 -> 0.045179773
B13: 2024-06-17 | C13: -0.75 | E13: -50.18 | G13: 2024-06-21 | H13: 2.02 | I13: -0.11 | J13: =VALUE(G13) -> 45464 | L13: =VALUE(B13) -> 45460 | M13: =SUM($D$7:D13) -> 150 | N13: =-SUMIFS(I:I,J:J,"<="&L13) -> 100.81 | O13: =SUMIFS(H:H,J:J,"<="&L13) -> 0 | P13: =IFERROR(O13/N13,0) -> 0 | Q13: =IFERROR((P13+1)^(12/((MAX($J$7:J13)-$J$7)/30.5))-1,0) -> 0 | R13: =N13/M13 -> 0.67206667 | AL13: Ganancias realizadas | AM13: =PVT!V16 -> 51.7 | AN13: =PVT!W16 -> 0.03468658
B14: 2024-06-18 | C14: -0.01 | G14: 2024-06-24 | H14: 0 | J14: =VALUE(G14) -> 45467 | L14: =VALUE(B14) -> 45461 | M14: =SUM($D$7:D14) -> 150 | N14: =-SUMIFS(I:I,J:J,"<="&L14) -> 100.81 | O14: =SUMIFS(H:H,J:J,"<="&L14) -> 0 | P14: =IFERROR(O14/N14,0) -> 0 | Q14: =IFERROR((P14+1)^(12/((MAX($J$7:J14)-$J$7)/30.5))-1,0) -> 0 | R14: =N14/M14 -> 0.67206667 | AL14: Dividendos | AM14: =PVT!V17 -> 14.79 | AN14: =PVT!W17 -> 0.0099229113
B15: 2024-06-21 | C15: 0.56 | E15: 0.33 | G15: 2024-06-28 | H15: 0 | J15: =VALUE(G15) -> 45471 | L15: =VALUE(B15) -> 45464 | M15: =SUM($D$7:D15) -> 150 | N15: =-SUMIFS(I:I,J:J,"<="&L15) -> 100.92 | O15: =SUMIFS(H:H,J:J,"<="&L15) -> 2.02 | P15: =IFERROR(O15/N15,0) -> 0.020015854 | Q15: =IFERROR((P15+1)^(12/((MAX($J$7:J15)-$J$7)/30.5))-1,0) -> 0.33661195 | R15: =N15/M15 -> 0.6728 | AL15: Efectivo disponible | AM15: =PVT!V18 -> 85.05 | AN15: =PVT!W18 -> 0.057061772
B16: 2024-06-24 | C16: 0 | G16: 2024-07-03 | I16: -36.03 | J16: =VALUE(G16) -> 45476 | L16: =VALUE(B16) -> 45467 | M16: =SUM($D$7:D16) -> 150 | N16: =-SUMIFS(I:I,J:J,"<="&L16) -> 100.92 | O16: =SUMIFS(H:H,J:J,"<="&L16) -> 2.02 | P16: =IFERROR(O16/N16,0) -> 0.020015854 | Q16: =IFERROR((P16+1)^(12/((MAX($J$7:J16)-$J$7)/30.5))-1,0) -> 0.27351613 | R16: =N16/M16 -> 0.6728 | AL16: Retornos totales | AM16: =PVT!V19 -> 66.49 | AN16: =PVT!W19 -> 0.044609491
B17: 2024-06-28 | C17: 0 | G17: 2024-07-05 | H17: 3.7 | I17: -19.95 | J17: =VALUE(G17) -> 45478 | L17: =VALUE(B17) -> 45471 | M17: =SUM($D$7:D17) -> 150 | N17: =-SUMIFS(I:I,J:J,"<="&L17) -> 100.92 | O17: =SUMIFS(H:H,J:J,"<="&L17) -> 2.02 | P17: =IFERROR(O17/N17,0) -> 0.020015854 | Q17: =IFERROR((P17+1)^(12/((MAX($J$7:J17)-$J$7)/30.5))-1,0) -> 0.25441625 | R17: =N17/M17 -> 0.6728 | AL17: Impustos y Gastos | AM17: =PVT!V20 -> -3.94 | AN17: =PVT!W20 -> -0.002643426
B18: 2024-07-02 | D18: 50 | G18: 2024-07-08 | H18: 0.65 | I18: 39.55 | J18: =VALUE(G18) -> 45481 | L18: =VALUE(B18) -> 45475 | M18: =SUM($D$7:D18) -> 200 | N18: =-SUMIFS(I:I,J:J,"<="&L18) -> 100.92 | O18: =SUMIFS(H:H,J:J,"<="&L18) -> 2.02 | P18: =IFERROR(O18/N18,0) -> 0.020015854 | Q18: =IFERROR((P18+1)^(12/((MAX($J$7:J18)-$J$7)/30.5))-1,0) -> 0.23027957 | R18: =N18/M18 -> 0.5046 | AL18: Ganancias y Perdidas | AM18: =PVT!V21 -> 129.89 | AN18: =PVT!W21 -> 0.087145838
B19: 2024-07-03 | E19: -36.03 | G19: 2024-07-09 | H19: -0.31 | I19: -24.98 | J19: =VALUE(G19) -> 45482 | L19: =VALUE(B19) -> 45476 | M19: =SUM($D$7:D19) -> 200 | N19: =-SUMIFS(I:I,J:J,"<="&L19) -> 136.95 | O19: =SUMIFS(H:H,J:J,"<="&L19) -> 2.02 | P19: =IFERROR(O19/N19,0) -> 0.014749909 | Q19: =IFERROR((P19+1)^(12/((MAX($J$7:J19)-$J$7)/30.5))-1,0) -> 0.1605131 | R19: =N19/M19 -> 0.68475 | AL19: Flujo de Caja Libre | AM19: =PVT!V22 -> 62.55 | AN19: =PVT!W22 -> 0.041966065
B20: 2024-07-05 | C20: 3.7 | E20: -19.95 | G20: 2024-07-10 | H20: 0 | I20: -24.49 | J20: =VALUE(G20) -> 45483 | L20: =VALUE(B20) -> 45478 | M20: =SUM($D$7:D20) -> 200 | N20: =-SUMIFS(I:I,J:J,"<="&L20) -> 156.9 | O20: =SUMIFS(H:H,J:J,"<="&L20) -> 5.72 | P20: =IFERROR(O20/N20,0) -> 0.036456342 | Q20: =IFERROR((P20+1)^(12/((MAX($J$7:J20)-$J$7)/30.5))-1,0) -> 0.42504619 | R20: =N20/M20 -> 0.7845
B21: 2024-07-08 | C21: 0.65 | E21: 19.28 | G21: 2024-07-11 | H21: 0.78 | I21: -27.89 | J21: =VALUE(G21) -> 45484 | L21: =VALUE(B21) -> 45481 | M21: =SUM($D$7:D21) -> 200 | N21: =-SUMIFS(I:I,J:J,"<="&L21) -> 117.35 | O21: =SUMIFS(H:H,J:J,"<="&L21) -> 6.37 | P21: =IFERROR(O21/N21,0) -> 0.054282062 | Q21: =IFERROR((P21+1)^(12/((MAX($J$7:J21)-$J$7)/30.5))-1,0) -> 0.66383555 | R21: =N21/M21 -> 0.58675 | AL21: =PVT!U24 -> Portfolio Metrics
B22: 2024-07-09 | C22: -4.58 | E22: -2.09 | G22: 2024-07-12 | H22: 0 | J22: =VALUE(G22) -> 45485 | L22: =VALUE(B22) -> 45482 | M22: =SUM($D$7:D22) -> 200 | N22: =-SUMIFS(I:I,J:J,"<="&L22) -> 142.33 | O22: =SUMIFS(H:H,J:J,"<="&L22) -> 6.06 | P22: =IFERROR(O22/N22,0) -> 0.04257711 | Q22: =IFERROR((P22+1)^(12/((MAX($J$7:J22)-$J$7)/30.5))-1,0) -> 0.47889846 | R22: =N22/M22 -> 0.71165 | AL22: Periodo de Inversion (Mes) | AM22: =PVT!V25 -> 10.880315
B23: 2024-07-10 | C23: -0.21 | E23: -4.26 | G23: 2024-08-07 | I23: -44.97 | J23: =VALUE(G23) -> 45511 | L23: =VALUE(B23) -> 45483 | M23: =SUM($D$7:D23) -> 200 | N23: =-SUMIFS(I:I,J:J,"<="&L23) -> 166.82 | O23: =SUMIFS(H:H,J:J,"<="&L23) -> 6.06 | P23: =IFERROR(O23/N23,0) -> 0.03632658 | Q23: =IFERROR((P23+1)^(12/((MAX($J$7:J23)-$J$7)/30.5))-1,0) -> 0.22252567 | R23: =N23/M23 -> 0.8341 | AL23: Retorno total % | AM23: =PVT!V26 -> 0.087145838
B24: 2024-07-11 | C24: 1.02 | E24: -7.62 | G24: 2024-08-14 | I24: -35 | J24: =VALUE(G24) -> 45518 | L24: =VALUE(B24) -> 45484 | M24: =SUM($D$7:D24) -> 200 | N24: =-SUMIFS(I:I,J:J,"<="&L24) -> 194.71 | O24: =SUMIFS(H:H,J:J,"<="&L24) -> 6.84 | P24: =IFERROR(O24/N24,0) -> 0.035129166 | Q24: =IFERROR((P24+1)^(12/((MAX($J$7:J24)-$J$7)/30.5))-1,0) -> 0.19185185 | R24: =N24/M24 -> 0.97355 | AL24: Retorno mensual % | AM24: =PVT!V27 -> 0.0080094959
B25: 2024-07-12 | C25: 0 | G25: 2024-08-15 | H25: 0.01 | J25: =VALUE(G25) -> 45519 | L25: =VALUE(B25) -> 45485 | M25: =SUM($D$7:D25) -> 200 | N25: =-SUMIFS(I:I,J:J,"<="&L25) -> 194.71 | O25: =SUMIFS(H:H,J:J,"<="&L25) -> 6.84 | P25: =IFERROR(O25/N25,0) -> 0.035129166 | Q25: =IFERROR((P25+1)^(12/((MAX($J$7:J25)-$J$7)/30.5))-1,0) -> 0.18898981 | R25: =N25/M25 -> 0.97355 | AL25: Retotrno Anualizado % | AM25: =PVT!V28 -> 0.096534142
B26: 2024-07-22 | D26: 50 | G26: 2024-08-19 | I26: -19.97 | J26: =VALUE(G26) -> 45523 | L26: =VALUE(B26) -> 45495 | M26: =SUM($D$7:D26) -> 250 | N26: =-SUMIFS(I:I,J:J,"<="&L26) -> 194.71 | O26: =SUMIFS(H:H,J:J,"<="&L26) -> 6.84 | P26: =IFERROR(O26/N26,0) -> 0.035129166 | Q26: =IFERROR((P26+1)^(12/((MAX($J$7:J26)-$J$7)/30.5))-1,0) -> 0.17834585 | R26: =N26/M26 -> 0.77884 | AL26: Flujo de efectico total % | AM26: =PVT!V29 -> 0.041966065
B27: 2024-07-23 | C27: -0.01 | E27: -44.89 | G27: 2024-09-03 | H27: 0.02 | J27: =VALUE(G27) -> 45538 | L27: =VALUE(B27) -> 45496 | M27: =SUM($D$7:D27) -> 250 | N27: =-SUMIFS(I:I,J:J,"<="&L27) -> 194.71 | O27: =SUMIFS(H:H,J:J,"<="&L27) -> 6.84 | P27: =IFERROR(O27/N27,0) -> 0.035129166 | Q27: =IFERROR((P27+1)^(12/((MAX($J$7:J27)-$J$7)/30.5))-1,0) -> 0.14723454 | R27: =N27/M27 -> 0.77884 | AL27: Flujo de caja mensual % | AM27: =PVT!V30 -> 0.0038570634
B28: 2024-07-24 | C28: -0.02 | E28: 12.65 | G28: 2024-09-09 | I28: -31.18 | J28: =VALUE(G28) -> 45544 | L28: =VALUE(B28) -> 45497 | M28: =SUM($D$7:D28) -> 250 | N28: =-SUMIFS(I:I,J:J,"<="&L28) -> 194.71 | O28: =SUMIFS(H:H,J:J,"<="&L28) -> 6.84 | P28: =IFERROR(O28/N28,0) -> 0.035129166 | Q28: =IFERROR((P28+1)^(12/((MAX($J$7:J28)-$J$7)/30.5))-1,0) -> 0.13762739 | R28: =N28/M28 -> 0.77884 | AL28: Flujo de caja annual % | AM28: =PVT!V31 -> 0.046383476
B29: 2024-07-31 | C29: 0.01 | E29: -12.57 | G29: 2024-09-12 | H29: 0.03 | J29: =VALUE(G29) -> 45547 | L29: =VALUE(B29) -> 45504 | M29: =SUM($D$7:D29) -> 250 | N29: =-SUMIFS(I:I,J:J,"<="&L29) -> 194.71 | O29: =SUMIFS(H:H,J:J,"<="&L29) -> 6.84 | P29: =IFERROR(O29/N29,0) -> 0.035129166 | Q29: =IFERROR((P29+1)^(12/((MAX($J$7:J29)-$J$7)/30.5))-1,0) -> 0.13327855 | R29: =N29/M29 -> 0.77884
B30: 2024-08-06 | D30: 50 | G30: 2024-09-13 | I30: -14.83 | J30: =VALUE(G30) -> 45548 | L30: =VALUE(B30) -> 45510 | M30: =SUM($D$7:D30) -> 300 | N30: =-SUMIFS(I:I,J:J,"<="&L30) -> 194.71 | O30: =SUMIFS(H:H,J:J,"<="&L30) -> 6.84 | P30: =IFERROR(O30/N30,0) -> 0.035129166 | Q30: =IFERROR((P30+1)^(12/((MAX($J$7:J30)-$J$7)/30.5))-1,0) -> 0.13188931 | R30: =N30/M30 -> 0.64903333
B31: 2024-08-07 | C31: -0.19 | E31: -44.97 | G31: 2024-09-16 | H31: 1.78 | I31: 15 | J31: =VALUE(G31) -> 45551 | L31: =VALUE(B31) -> 45511 | M31: =SUM($D$7:D31) -> 300 | N31: =-SUMIFS(I:I,J:J,"<="&L31) -> 239.68 | O31: =SUMIFS(H:H,J:J,"<="&L31) -> 6.84 | P31: =IFERROR(O31/N31,0) -> 0.028538051 | Q31: =IFERROR((P31+1)^(12/((MAX($J$7:J31)-$J$7)/30.5))-1,0) -> 0.1030538 | R31: =N31/M31 -> 0.79893333
B32: 2024-08-08 | C32: 0 | G32: 2024-09-17 | H32: 0 | J32: =VALUE(G32) -> 45552 | L32: =VALUE(B32) -> 45512 | M32: =SUM($D$7:D32) -> 300 | N32: =-SUMIFS(I:I,J:J,"<="&L32) -> 239.68 | O32: =SUMIFS(H:H,J:J,"<="&L32) -> 6.84 | P32: =IFERROR(O32/N32,0) -> 0.028538051 | Q32: =IFERROR((P32+1)^(12/((MAX($J$7:J32)-$J$7)/30.5))-1,0) -> 0.10203361 | R32: =N32/M32 -> 0.79893333
B33: 2024-08-14 | D33: 50 | E33: -35 | G33: 2024-09-18 | I33: -20 | J33: =VALUE(G33) -> 45553 | L33: =VALUE(B33) -> 45518 | M33: =SUM($D$7:D33) -> 350 | N33: =-SUMIFS(I:I,J:J,"<="&L33) -> 274.68 | O33: =SUMIFS(H:H,J:J,"<="&L33) -> 6.84 | P33: =IFERROR(O33/N33,0) -> 0.024901704 | Q33: =IFERROR((P33+1)^(12/((MAX($J$7:J33)-$J$7)/30.5))-1,0) -> 0.087775231 | R33: =N33/M33 -> 0.7848
B34: 2024-08-15 | C34: 0.01 | G34: 2024-09-24 | H34: -3.95 | I34: 0.29 | J34: =VALUE(G34) -> 45559 | L34: =VALUE(B34) -> 45519 | M34: =SUM($D$7:D34) -> 350 | N34: =-SUMIFS(I:I,J:J,"<="&L34) -> 274.68 | O34: =SUMIFS(H:H,J:J,"<="&L34) -> 6.85 | P34: =IFERROR(O34/N34,0) -> 0.02493811 | Q34: =IFERROR((P34+1)^(12/((MAX($J$7:J34)-$J$7)/30.5))-1,0) -> 0.083051226 | R34: =N34/M34 -> 0.7848
B35: 2024-08-19 | E35: -19.97 | G35: 2024-09-25 | H35: -3.78 | I35: 5 | J35: =VALUE(G35) -> 45560 | L35: =VALUE(B35) -> 45523 | M35: =SUM($D$7:D35) -> 350 | N35: =-SUMIFS(I:I,J:J,"<="&L35) -> 294.65 | O35: =SUMIFS(H:H,J:J,"<="&L35) -> 6.85 | P35: =IFERROR(O35/N35,0) -> 0.023247921 | Q35: =IFERROR((P35+1)^(12/((MAX($J$7:J35)-$J$7)/30.5))-1,0) -> 0.076573906 | R35: =N35/M35 -> 0.84185714
B36: 2024-09-03 | C36: 0.02 | G36: 2024-09-26 | H36: 0.08 | J36: =VALUE(G36) -> 45561 | L36: =VALUE(B36) -> 45538 | M36: =SUM($D$7:D36) -> 350 | N36: =-SUMIFS(I:I,J:J,"<="&L36) -> 294.65 | O36: =SUMIFS(H:H,J:J,"<="&L36) -> 6.87 | P36: =IFERROR(O36/N36,0) -> 0.023315798 | Q36: =IFERROR((P36+1)^(12/((MAX($J$7:J36)-$J$7)/30.5))-1,0) -> 0.076110556 | R36: =N36/M36 -> 0.84185714
B37: 2024-09-04 | D37: 50 | G37: 2024-09-30 | H37: 0.11 | J37: =VALUE(G37) -> 45565 | L37: =VALUE(B37) -> 45539 | M37: =SUM($D$7:D37) -> 400 | N37: =-SUMIFS(I:I,J:J,"<="&L37) -> 294.65 | O37: =SUMIFS(H:H,J:J,"<="&L37) -> 6.87 | P37: =IFERROR(O37/N37,0) -> 0.023315798 | Q37: =IFERROR((P37+1)^(12/((MAX($J$7:J37)-$J$7)/30.5))-1,0) -> 0.073460508 | R37: =N37/M37 -> 0.736625
B38: 2024-09-09 | E38: -31.18 | G38: 2024-10-03 | I38: -29.97 | J38: =VALUE(G38) -> 45568 | L38: =VALUE(B38) -> 45544 | M38: =SUM($D$7:D38) -> 400 | N38: =-SUMIFS(I:I,J:J,"<="&L38) -> 325.83 | O38: =SUMIFS(H:H,J:J,"<="&L38) -> 6.87 | P38: =IFERROR(O38/N38,0) -> 0.021084615 | Q38: =IFERROR((P38+1)^(12/((MAX($J$7:J38)-$J$7)/30.5))-1,0) -> 0.0645969 | R38: =N38/M38 -> 0.814575
B39: 2024-09-12 | C39: 0.03 | G39: 2024-10-09 | H39: 0.06 | J39: =VALUE(G39) -> 45574 | L39: =VALUE(B39) -> 45547 | M39: =SUM($D$7:D39) -> 400 | N39: =-SUMIFS(I:I,J:J,"<="&L39) -> 325.83 | O39: =SUMIFS(H:H,J:J,"<="&L39) -> 6.9 | P39: =IFERROR(O39/N39,0) -> 0.021176687 | Q39: =IFERROR((P39+1)^(12/((MAX($J$7:J39)-$J$7)/30.5))-1,0) -> 0.061751448 | R39: =N39/M39 -> 0.814575
B40: 2024-09-13 | E40: -14.83 | G40: 2024-10-10 | H40: 0.49 | J40: =VALUE(G40) -> 45575 | L40: =VALUE(B40) -> 45548 | M40: =SUM($D$7:D40) -> 400 | N40: =-SUMIFS(I:I,J:J,"<="&L40) -> 340.66 | O40: =SUMIFS(H:H,J:J,"<="&L40) -> 6.9 | P40: =IFERROR(O40/N40,0) -> 0.0202548 | Q40: =IFERROR((P40+1)^(12/((MAX($J$7:J40)-$J$7)/30.5))-1,0) -> 0.058542386 | R40: =N40/M40 -> 0.85165
B41: 2024-09-16 | C41: 1.78 | E41: 15 | G41: 2024-10-15 | I41: -39.99 | J41: =VALUE(G41) -> 45580 | L41: =VALUE(B41) -> 45551 | M41: =SUM($D$7:D41) -> 400 | N41: =-SUMIFS(I:I,J:J,"<="&L41) -> 325.66 | O41: =SUMIFS(H:H,J:J,"<="&L41) -> 8.68 | P41: =IFERROR(O41/N41,0) -> 0.026653565 | Q41: =IFERROR((P41+1)^(12/((MAX($J$7:J41)-$J$7)/30.5))-1,0) -> 0.074490663 | R41: =N41/M41 -> 0.81415
B42: 2024-09-17 | C42: 0 | G42: 2024-10-17 | I42: -12.98 | J42: =VALUE(G42) -> 45582 | L42: =VALUE(B42) -> 45552 | M42: =SUM($D$7:D42) -> 400 | N42: =-SUMIFS(I:I,J:J,"<="&L42) -> 325.66 | O42: =SUMIFS(H:H,J:J,"<="&L42) -> 8.68 | P42: =IFERROR(O42/N42,0) -> 0.026653565 | Q42: =IFERROR((P42+1)^(12/((MAX($J$7:J42)-$J$7)/30.5))-1,0) -> 0.073355988 | R42: =N42/M42 -> 0.81415
B43: 2024-09-18 | E43: -20 | G43: 2024-10-18 | I43: -20.48 | J43: =VALUE(G43) -> 45583 | L43: =VALUE(B43) -> 45553 | M43: =SUM($D$7:D43) -> 400 | N43: =-SUMIFS(I:I,J:J,"<="&L43) -> 345.66 | O43: =SUMIFS(H:H,J:J,"<="&L43) -> 8.68 | P43: =IFERROR(O43/N43,0) -> 0.025111381 | Q43: =IFERROR((P43+1)^(12/((MAX($J$7:J43)-$J$7)/30.5))-1,0) -> 0.068501725 | R43: =N43/M43 -> 0.86415
B44: 2024-09-24 | C44: -3.95 | D44: 50 | E44: 0.29 | G44: 2024-10-28 | I44: -14.98 | J44: =VALUE(G44) -> 45593 | L44: =VALUE(B44) -> 45559 | M44: =SUM($D$7:D44) -> 450 | N44: =-SUMIFS(I:I,J:J,"<="&L44) -> 345.37 | O44: =SUMIFS(H:H,J:J,"<="&L44) -> 4.73 | P44: =IFERROR(O44/N44,0) -> 0.013695457 | Q44: =IFERROR((P44+1)^(12/((MAX($J$7:J44)-$J$7)/30.5))-1,0) -> 0.034447537 | R44: =N44/M44 -> 0.76748889
...

Sheet Positions
B11: InReport | C11: TRUE
B13: Chapter | C13: Symbol | D13: Start Date | E13: Volume | F13: Entry Price USD | G13: Holding Period (Mon) | H13: Entry Value USD | I13: Market Value USD | J13: Unrealized Gains | K13: Unrealized Gains %
B14: Consumer Defensive | C14: PEP | D14: 45460.885 | E14: 0.6548 | F14: 151.03849 | G14: 10.880315 | H14: 98.9 | I14: 86.11 | J14: -12.79 | K14: -0.12932255
B15: Consumer Defensive | C15: MO | D15: 45518.844 | E15: 1.7987 | F15: 52.676933 | G15: 8.98002 | H15: 94.75 | I15: 104.22 | J15: 9.47 | K15: 0.09994723
B16: Consumer Defensive | C16: ACI | D16: 45693.855 | E16: 4 | F16: 20.95 | G16: 3.2419632 | H16: 83.8 | I16: 87.6 | J16: 3.8 | K16: 0.045346062
B17: Consumer Defensive | C17: KMB | D17: 45544.652 | E17: 0.4 | F17: 135.975 | G17: 8.1338774 | H17: 54.39 | I17: 54.95 | J17: 0.56 | K17: 0.01029601
B18: Consumer Defensive | C18: INGR | D18: 45580.706 | E18: 0.3486 | F18: 131.92771 | G18: 6.9517513 | H18: 45.99 | I18: 48.37 | J18: 2.38 | K18: 0.051750381
B19: Consumer Defensive | C19: DAR | D19: 45708.681 | E19: 0.8121 | F19: 36.916636 | G19: 2.7558539 | H19: 29.98 | I19: 28.67 | J19: -1.31 | K19: -0.043695797
B20: ETF | C20: BND | D20: 45743.774 | E20: 2 | F20: 73.5 | G20: 1.6052787 | H20: 147 | I20: 144.84 | J20: -2.16 | K20: -0.014693878
B21: ETF | C21: VWO | D21: 45686.833 | E21: 3 | F21: 44.946667 | G21: 3.4722024 | H21: 134.84 | I21: 143.07 | J21: 8.23 | K21: 0.061035301
B22: ETF | C22: BOTZ.UK | D22: 45482.713 | E22: 2 | F22: 20.925 | G22: 10.164654 | H22: 41.85 | I22: 40.65 | J22: -1.2 | K22: -0.028673835
B23: ETF | C23: BATT.NL | D23: 45484.679 | E23: 2 | F23: 17.505 | G23: 10.100201 | H23: 35.01 | I23: 35.74 | J23: 0.73 | K23: 0.020851185
B24: Energy & Utilities | C24: APA | D24: 45632.877 | E24: 5.7971 | F24: 18.968105 | G24: 5.2412533 | H24: 109.96 | I24: 102.84 | J24: -7.12 | K24: -0.064750818
B25: Energy & Utilities | C25: YPF | D25: 45663.738 | E25: 2.2045 | F25: 36.289408 | G25: 4.2294227 | H25: 80 | I25: 78.64 | J25: -1.36 | K25: -0.017
... B40: Consumer Cyclical | C40: YUM | D40: 45645.901 | E40: 0.0003 | F40: 133.33333 | G40: 4.8142337 | H40: 0.04 | I40: 0.04 | J40: 0 | K40: 0
B41: Grand Total | D41: 45460.885 | E41: 37.5471 | F41: 40.495538 | G41: 10.880315 | H41: 1520.49 | I41: 1585.25 | J41: 64.76 | K41: 0.042591533

Sheet CLOSED POSITION HISTORY
J6: Name and surname | M6: Account | P6: Currency | Y6: 45793.063
J7: SAMUEL EDUARDO RODRIGUEZ WALTON | M7: 50704832 | P7: USD
J8: Balance | M8: Equity | P8: Margin | S8: Free margin | V8: Margin level
J9: 85.05 | M9: 1605.25 | P9: 0 | S9: 85.05 | V9: 0
B10: CLOSED POSITION HISTORY
B11: 01/01/2006 - 16/05/2025
B12: Balance :
B13: Position | C13: Symbol | D13: Chapter | E13: ToM | F13: Type | G13: InReport | H13: Type | I13: Volume | J13: Open time | K13: Open price | L13: Close time | M13: Close price | N13: Open origin | O13: Close origin | P13: Purchase value | Q13: Sale value | R13: SL | S13: TP | T13: Margin | U13: Commission | V13: Swap | W13: Rollover | X13: Gross P/L | Y13: Comment
B14: 1345716305 | C14: NVDA | D14: =IFERROR(INDEX([1]Positions!$A:$A,MATCH(C14,[1]Positions!$C:$C,0)),"Other") -> Technology | E14: =(L14-J14)/30.5 -> 0.12621084 | F14: =IF(ISBLANK(T14),"Stock Holding","SWAP Contract") -> Stock Holding | G14: =ISNUMBER(I14) -> TRUE | H14: BUY | I14: 0.0171 | J14: 45448.646 | K14: 1184.19 | L14: 45452.495 | M14: 1184.19 | N14: xStation Mobile iOS | O14: correction | P14: 20.25 | Q14: 20.25 | U14: 0 | V14: 0 | W14: 0 | X14: 0 | Y14: STC Transfer Out
B15: 1393281432 | C15: FLOA.UK | D15: =IFERROR(INDEX([1]Positions!$A:$A,MATCH(C15,[1]Positions!$C:$C,0)),"Other") -> MISC | E15: =(L15-J15)/30.5 -> 0.007937333 | F15: =IF(ISBLANK(T15),"Stock Holding","SWAP Contract") -> Stock Holding | G15: =ISNUMBER(I15) -> TRUE | H15: BUY | I15: 0.632 | J15: 45496.376 | K15: 5.981 | L15: 45496.618 | M15: 5.967 | N15: xStation 5 | O15: xStation 5 | P15: 3.78 | Q15: 3.77 | U15: 0 | V15: 0 | W15: 0 | X15: -0.01
B16: 1393281260 | C16: SDIA.UK | D16: =IFERROR(INDEX([1]Positions!$A:$A,MATCH(C16,[1]Positions!$C:$C,0)),"Other") -> MISC | E16: =(L16-J16)/30.5 -> 0.0079381755 | F16: =IF(ISBLANK(T16),"Stock Holding","SWAP Contract") -> Stock Holding | G16: =ISNUMBER(I16) -> TRUE | H16: BUY | I16: 0.5612 | J16: 45496.376 | K16: 5.812 | L16: 45496.618 | M16: 5.81 | N16: xStation 5 | O16: xStation 5 | P16: 3.26 | Q16: 3.26 | U16: 0 | V16: 0 | W16: 0 | X16: 0
B17: 1342063955 | C17: SHELL.NL | D17: =IFERROR(INDEX([1]Positions!$A:$A,MATCH(C17,[1]Positions!$C:$C,0)),"Other") -> MISC | E17: =(L17-J17)/30.5 -> 0.23895908 | F17: =IF(ISBLANK(T17),"Stock Holding","SWAP Contract") -> Stock Holding | G17: =ISNUMBER(I17) -> TRUE | H17: BUY | I17: 0.4139 | J17: 45446.375 | K17: 33.545 | L17: 45453.664 | M17: 32.605 | N17: xStation Mobile iOS | O17: xStation Mobile iOS | P17: 15.15 | Q17: 14.42 | U17: 0 | V17: 0 | W17: 0 | X17: -0.73
B18: 1393281260 | C18: SDIA.UK | D18: =IFERROR(INDEX([1]Positions!$A:$A,MATCH(C18,[1]Positions!$C:$C,0)),"Other") -> MISC | E18: =(L18-J18)/30.5 -> 0.041921144 | F18: =IF(ISBLANK(T18),"Stock Holding","SWAP Contract") -> Stock Holding | G18: =ISNUMBER(I18) -> TRUE | H18: BUY | I18: 0.555 | J18: 45496.376 | K18: 5.812 | L18: 45497.654 | M18: 5.801 | N18: xStation 5 | O18: xStation 5 | P18: 3.23 | Q18: 3.22 | U18: 0 | V18: 0 | W18: 0 | X18: -0.01
B19: 1393281432 | C19: FLOA.UK | D19: =IFERROR(INDEX([1]Positions!$A:$A,MATCH(C19,[1]Positions!$C:$C,0)),"Other") -> MISC | E19: =(L19-J19)/30.5 -> 0.041920327 | F19: =IF(ISBLANK(T19),"Stock Holding","SWAP Contract") -> Stock Holding | G19: =ISNUMBER(I19) -> TRUE | H19: BUY | I19: 0.4344 | J19: 45496.376 | K19: 5.981 | L19: 45497.654 | M19: 5.968 | N19: xStation 5 | O19: xStation 5 | P19: 2.6 | Q19: 2.59 | U19: 0 | V19: 0 | W19: 0 | X19: -0.01
B20: 1393281260 | C20: SDIA.UK | D20: =IFERROR(INDEX([1]Positions!$A:$A,MATCH(C20,[1]Positions!$C:$C,0)),"Other") -> MISC | E20: =(L20-J20)/30.5 -> 0.041921401 | F20: =IF(ISBLANK(T20),"Stock Holding","SWAP Contract") -> Stock Holding | G20: =ISNUMBER(I20) -> TRUE | H20: BUY | I20: 1 | J20: 45496.376 | K20: 5.812 | L20: 45497.654 | M20: 5.814 | N20: xStation 5 | O20: xStation 5 | P20: 5.81 | Q20: 5.81 | U20: 0 | V20: 0 | W20: 0 | X20: 0
B21: 1393281432 | C21: FLOA.UK | D21: =IFERROR(INDEX([1]Positions!$A:$A,MATCH(C21,[1]Positions!$C:$C,0)),"Other") -> MISC | E21: =(L21-J21)/30.5 -> 0.041920625 | F21: =IF(ISBLANK(T21),"Stock Holding","SWAP Contract") -> Stock Holding | G21: =ISNUMBER(I21) -> TRUE | H21: BUY | I21: 1 | J21: 45496.376 | K21: 5.981 | L21: 45497.654 | M21: 5.978 | N21: xStation 5 | O21: xStation 5 | P21: 5.98 | Q21: 5.98 | U21: 0 | V21: 0 | W21: 0 | X21: 0
B22: 1350877137 | C22: US30 | D22: =IFERROR(INDEX([1]Positions!$A:$A,MATCH(C22,[1]Positions!$C:$C,0)),"Other") -> Other | E22: =(L22-J22)/30.5 -> 0.00013678241 | F22: =IF(ISBLANK(T22),"Stock Holding","SWAP Contract") -> SWAP Contract | G22: =ISNUMBER(I22) -> TRUE | H22: BUY | I22: 0.01 | J22: 45453.906 | K22: 38900 | L22: 45453.91 | M22: 38869 | N22: xStation Mobile iOS | O22: pending(t/p|s/l) | R22: 38874 | S22: 38933 | T22: 9.73 | U22: 0 | V22: 0 | W22: 0 | X22: -1.55 | Y22: [S/L]
B23: 1393281260 | C23: SDIA.UK | D23: =IFERROR(INDEX([1]Positions!$A:$A,MATCH(C23,[1]Positions!$C:$C,0)),"Other") -> MISC | E23: =(L23-J23)/30.5 -> 0.27081714 | F23: =IF(ISBLANK(T23),"Stock Holding","SWAP Contract") -> Stock Holding | G23: =ISNUMBER(I23) -> TRUE | H23: BUY | I23: 0.4206 | J23: 45496.376 | K23: 5.812 | L23: 45504.636 | M23: 5.826 | N23: xStation 5 | O23: xStation 5 | P23: 2.44 | Q23: 2.45 | U23: 0 | V23: 0 | W23: 0 | X23: 0.01
B24: 1393281432 | C24: FLOA.UK | D24: =IFERROR(INDEX([1]Positions!$A:$A,MATCH(C24,[1]Positions!$C:$C,0)),"Other") -> MISC | E24: =(L24-J24)/30.5 -> 0.27081632 | F24: =IF(ISBLANK(T24),"Stock Holding","SWAP Contract") -> Stock Holding | G24: =ISNUMBER(I24) -> TRUE | H24: BUY | I24: 0.4033 | J24: 45496.376 | K24: 5.981 | L24: 45504.636 | M24: 5.98 | N24: xStation 5 | O24: xStation 5 | P24: 2.41 | Q24: 2.41 | U24: 0 | V24: 0 | W24: 0 | X24: 0
B25: 1357581812 | C25: PEP | D25: =IFERROR(INDEX([1]Positions!$A:$A,MATCH(C25,[1]Positions!$C:$C,0)),"Other") -> Consumer Defensive | E25: =(L25-J25)/30.5 -> 0.0030362018 | F25: =IF(ISBLANK(T25),"Stock Holding","SWAP Contract") -> Stock Holding | G25: =ISNUMBER(I25) -> TRUE | H25: BUY | I25: 0.123 | J25: 45460.646 | K25: 1.65 | L25: 45460.738 | M25: 165.24 | N25: xStation Mobile iOS | O25: correction | P25: 0.2 | Q25: 20.32 | U25: 0 | V25: 0 | W25: 0 | X25: 0
B26: 1393281432 | C26: FLOA.UK | D26: =IFERROR(INDEX([1]Positions!$A:$A,MATCH(C26,[1]Positions!$C:$C,0)),"Other") -> MISC | E26: =(L26-J26)/30.5 -> 0.27101363 | F26: =IF(ISBLANK(T26),"Stock Holding","SWAP Contract") -> Stock Holding | G26: =ISNUMBER(I26) -> TRUE | H26: BUY | I26: 0.4201 | J26: 45496.376 | K26: 5.981 | L26: 45504.642 | M26: 5.98 | N26: xStation 5 | O26: xStation 5 | P26: 2.51 | Q26: 2.51 | U26: 0 | V26: 0 | W26: 0 | X26: 0
B27: 1393281432 | C27: FLOA.UK | D27: =IFERROR(INDEX([1]Positions!$A:$A,MATCH(C27,[1]Positions!$C:$C,0)),"Other") -> MISC | E27: =(L27-J27)/30.5 -> 7.5409692 | F27: =IF(ISBLANK(T27),"Stock Holding","SWAP Contract") -> Stock Holding | G27: =ISNUMBER(I27) -> TRUE | H27: BUY | I27: 1 | J27: 45496.376 | K27: 5.981 | L27: 45726.375 | M27: 6.186 | N27: xStation 5 | O27: xStation 5 | P27: 5.98 | Q27: 6.19 | U27: 0 | V27: 0 | W27: 0 | X27: 0.21
B28: 1393281260 | C28: SDIA.UK | D28: =IFERROR(INDEX([1]Positions!$A:$A,MATCH(C28,[1]Positions!$C:$C,0)),"Other") -> MISC | E28: =(L28-J28)/30.5 -> 7.5409712 | F28: =IF(ISBLANK(T28),"Stock Holding","SWAP Contract") -> Stock Holding | G28: =ISNUMBER(I28) -> TRUE | H28: BUY | I28: 1.4632 | J28: 45496.376 | K28: 5.812 | L28: 45726.375 | M28: 6.02 | N28: xStation 5 | O28: xStation 5 | P28: 8.5 | Q28: 8.81 | U28: 0 | V28: 0 | W28: 0 | X28: 0.3
B29: 1393287040 | C29: SDIA.UK | D29: =IFERROR(INDEX([1]Positions!$A:$A,MATCH(C29,[1]Positions!$C:$C,0)),"Other") -> MISC | E29: =(L29-J29)/30.5 -> 7.5409086 | F29: =IF(ISBLANK(T29),"Stock Holding","SWAP Contract") -> Stock Holding | G29: =ISNUMBER(I29) -> TRUE | H29: BUY | I29: 0.2503 | J29: 45496.378 | K29: 5.811 | L29: 45726.375 | M29: 6.02 | N29: xStation 5 | O29: xStation 5 | P29: 1.45 | Q29: 1.51 | U29: 0 | V29: 0 | W29: 0 | X29: 0.06
B30: 1403180431 | C30: SDIA.UK | D30: =IFERROR(INDEX([1]Positions!$A:$A,MATCH(C30,[1]Positions!$C:$C,0)),"Other") -> MISC | E30: =(L30-J30)/30.5 -> 7.2699105 | F30: =IF(ISBLANK(T30),"Stock Holding","SWAP Contract") -> Stock Holding | G30: =ISNUMBER(I30) -> TRUE | H30: BUY | I30: 0.2773 | J30: 45504.643 | K30: 5.84 | L30: 45726.375 | M30: 6.02 | N30: xStation 5 | O30: xStation 5 | P30: 1.62 | Q30: 1.67 | U30: 0 | V30: 0 | W30: 0 | X30: 0.05
B31: 1403180445 | C31: SDIA.UK | D31: =IFERROR(INDEX([1]Positions!$A:$A,MATCH(C31,[1]Positions!$C:$C,0)),"Other") -> MISC | E31: =(L31-J31)/30.5 -> 7.2699102 | F31: =IF(ISBLANK(T31),"Stock Holding","SWAP Contract") -> Stock Holding | G31: =ISNUMBER(I31) -> TRUE | H31: BUY | I31: 0.0092 | J31: 45504.643 | K31: 5.836 | L31: 45726.375 | M31: 6.02 | N31: xStation 5 | O31: xStation 5 | P31: 0.05 | Q31: 0.06 | U31: 0 | V31: 0 | W31: 0 | X31: 0.01
B32: 1343394966 | C32: SMFG | D32: =IFERROR(INDEX([1]Positions!$A:$A,MATCH(C32,[1]Positions!$C:$C,0)),"Other") -> MISC | E32: =(L32-J32)/30.5 -> 0.45839116 | F32: =IF(ISBLANK(T32),"Stock Holding","SWAP Contract") -> Stock Holding | G32: =ISNUMBER(I32) -> TRUE | H32: BUY | I32: 1 | J32: 45446.904 | K32: 13.37 | L32: 45460.885 | M32: 12.62 | N32: xStation Mobile iOS | O32: xStation Mobile iOS | P32: 13.37 | Q32: 12.62 | U32: 0 | V32: 0 | W32: 0 | X32: -0.75
B33: 1393735509 | C33: VHYD.UK | D33: =IFERROR(INDEX([1]Positions!$A:$A,MATCH(C33,[1]Positions!$C:$C,0)),"Other") -> MISC | E33: =(L33-J33)/30.5 -> 7.5330577 | F33: =IF(ISBLANK(T33),"Stock Holding","SWAP Contract") -> Stock Holding | G33: =ISNUMBER(I33) -> TRUE | H33: BUY | I33: 0.0366 | J33: 45496.618 | K33: 67.37 | L33: 45726.376 | M33: 71.16 | N33: xStation 5 | O33: xStation 5 | P33: 2.47 | Q33: 2.6 | U33: 0 | V33: 0 | W33: 0 | X33: 0.13
B34: 1395218355 | C34: VHYD.UK | D34: =IFERROR(INDEX([1]Positions!$A:$A,MATCH(C34,[1]Positions!$C:$C,0)),"Other") -> MISC | E34: =(L34-J34)/30.5 -> 7.4990754 | F34: =IF(ISBLANK(T34),"Stock Holding","SWAP Contract") -> Stock Holding | G34: =ISNUMBER(I34) -> TRUE | H34: BUY | I34: 0.074 | J34: 45497.654 | K34: 67.13 | L34: 45726.376 | M34: 71.16 | N34: xStation 5 | O34: xStation 5 | P34: 4.97 | Q34: 5.27 | U34: 0 | V34: 0 | W34: 0 | X34: 0.3
... B38: 1403180445 | C38: SDIA.UK | D38: =IFERROR(INDEX([1]Positions!$A:$A,MATCH(C38,[1]Positions!$C:$C,0)),"Other") -> MISC | E38: =(L38-J38)/30.5 -> 7.2717807 | F38: =IF(ISBLANK(T38),"Stock Holding","SWAP Contract") -> Stock Holding | G38: =ISNUMBER(I38) -> TRUE | H38: BUY | I38: 0.9908 | J38: 45504.643 | K38: 5.836 | L38: 45726.432 | M38: 6.027 | N38: xStation 5 | O38: xStation 5 | P38: 5.78 | Q38: 5.97 | U38: 0 | V38: 0 | W38: 0 | X38: 0.18
B39: 1349530190 | C39: NVDA | D39: =IFERROR(INDEX([1]Positions!$A:$A,MATCH(C39,[1]Positions!$C:$C,0)),"Other") -> Technology | E39: =(L39-J39)/30.5 -> 0.39350062 | F39: =IF(ISBLANK(T39),"Stock Holding","SWAP Contract") -> Stock Holding | G39: =ISNUMBER(I39) -> TRUE | H39: BUY | I39: 0.12 | J39: 45452.644 | K39: 118.42 | L39: 45464.646 | M39: 126.75 | N39: correction | O39: xStation Mobile iOS | P39: 14.21 | Q39: 15.21 | U39: 0 | V39: 0 | W39: 0 | X39: 1 | Y39: NVDA.US split 10 for 1
B40: 1393281432 | C40: FLOA.UK | D40: =IFERROR(INDEX([1]Positions!$A:$A,MATCH(C40,[1]Positions!$C:$C,0)),"Other") -> MISC | E40: =(L40-J40)/30.5 -> 7.5741219 | F40: =IF(ISBLANK(T40),"Stock Holding","SWAP Contract") -> Stock Holding | G40: =ISNUMBER(I40) -> TRUE | H40: BUY | I40: 0.1102 | J40: 45496.376 | K40: 5.981 | L40: 45727.386 | M40: 6.176 | N40: xStation 5 | O40: xStation 5 | P40: 0.66 | Q40: 0.68 | U40: 0 | V40: 0 | W40: 0 | X40: 0.02
B41: 1393301698 | C41: FLOA.UK | D41: =IFERROR(INDEX([1]Positions!$A:$A,MATCH(C41,[1]Positions!$C:$C,0)),"Other") -> MISC | E41: =(L41-J41)/30.5 -> 7.5740171 | F41: =IF(ISBLANK(T41),"Stock Holding","SWAP Contract") -> Stock Holding | G41: =ISNUMBER(I41) -> TRUE | H41: BUY | I41: 0.1401 | J41: 45496.379 | K41: 5.99 | L41: 45727.386 | M41: 6.176 | N41: xStation 5 | O41: xStation 5 | P41: 0.84 | Q41: 0.87 | U41: 0 | V41: 0 | W41: 0 | X41: 0.03
B42: 1403180427 | C42: FLOA.UK | D42: =IFERROR(INDEX([1]Positions!$A:$A,MATCH(C42,[1]Positions!$C:$C,0)),"Other") -> MISC | E42: =(L42-J42)/30.5 -> 7.303062 | F42: =IF(ISBLANK(T42),"Stock Holding","SWAP Contract") -> Stock Holding | G42: =ISNUMBER(I42) -> TRUE | H42: BUY | I42: 0.4203 | J42: 45504.643 | K42: 5.989 | L42: 45727.386 | M42: 6.176 | N42: xStation 5 | O42: xStation 5 | P42: 2.52 | Q42: 2.6 | U42: 0 | V42: 0 | W42: 0 | X42: 0.08
B43: 1343379129 | C43: QCOM | D43: =IFERROR(INDEX([1]Positions!$A:$A,MATCH(C43,[1]Positions!$C:$C,0)),"Other") -> Technology | E43: =(L43-J43)/30.5 -> 0.5820396 | F43: =IF(ISBLANK(T43),"Stock Holding","SWAP Contract") -> Stock Holding | G43: =ISNUMBER(I43) -> TRUE | H43: BUY | I43: 0.0975 | J43: 45446.894 | K43: 205.08 | L43: 45464.646 | M43: 211.24 | N43: xStation Mobile iOS | O43: xStation Mobile iOS | P43: 20 | Q43: 20.6 | U43: 0 | V43: 0 | W43: 0 | X43: 0.6
B44: 1349530190 | C44: NVDA | D44: =IFERROR(INDEX([1]Positions!$A:$A,MATCH(C44,[1]Positions!$C:$C,0)),"Other") -> Technology | E44: =(L44-J44)/30.5 -> 0.39350065 | F44: =IF(ISBLANK(T44),"Stock Holding","SWAP Contract") -> Stock Holding | G44: =ISNUMBER(I44) -> TRUE | H44: BUY | I44: 0.051 | J44: 45452.644 | K44: 118.42 | L44: 45464.646 | M44: 126.76 | N44: correction | O44: xStation Mobile iOS | P44: 6.04 | Q44: 6.46 | U44: 0 | V44: 0 | W44: 0 | X44: 0.42 | Y44: NVDA.US split 10 for 1
B45: 1357737013 | C45: AVGO | D45: =IFERROR(INDEX([1]Positions!$A:$A,MATCH(C45,[1]Positions!$C:$C,0)),"Other") -> MISC | E45: =(L45-J45)/30.5 -> 0.13030328 | F45: =IF(ISBLANK(T45),"Stock Holding","SWAP Contract") -> Stock Holding | G45: =ISNUMBER(I45) -> TRUE | H45: BUY | I45: 0.0115 | J45: 45460.686 | K45: 1797.13 | L45: 45464.66 | M45: 1686.26 | N45: xStation Mobile iOS | O45: xStation Mobile iOS | P45: 20.67 | Q45: 19.39 | U45: 0 | V45: 0 | W45: 0 | X45: -1.28
B46: 1362492338 | C46: GILD | D46: =IFERROR(INDEX([1]Positions!$A:$A,MATCH(C46,[1]Positions!$C:$C,0)),"Other") -> MISC | E46: =(L46-J46)/30.5 -> 0.00018840278 | F46: =IF(ISBLANK(T46),"Stock Holding","SWAP Contract") -> Stock Holding | G46: =ISNUMBER(I46) -> TRUE | H46: BUY | I46: 0.2806 | J46: 45464.662 | K46: 71.61 | L46: 45464.667 | M46: 70.96 | N46: xStation Mobile iOS | O46: xStation Mobile iOS | P46: 20.09 | Q46: 19.91 | U46: 0 | V46: 0 | W46: 0 | X46: -0.18
B47: 1342641165 | C47: TSM | D47: =IFERROR(INDEX([1]Positions!$A:$A,MATCH(C47,[1]Positions!$C:$C,0)),"Other") -> Technology | E47: =(L47-J47)/30.5 -> 1.0493769 | F47: =IF(ISBLANK(T47),"Stock Holding","SWAP Contract") -> Stock Holding | G47: =ISNUMBER(I47) -> TRUE | H47: BUY | I47: 0.1322 | J47: 45446.646 | K47: 155.59 | L47: 45478.652 | M47: 183.6 | N47: xStation Mobile iOS | O47: xStation Mobile iOS | P47: 20.57 | Q47: 24.27 | U47: 0 | V47: 0 | W47: 0 | X47: 3.7
B48: 1347626622 | C48: WMT | D48: =IFERROR(INDEX([1]Positions!$A:$A,MATCH(C48,[1]Positions!$C:$C,0)),"Other") -> Consumer Defensive | E48: =(L48-J48)/30.5 -> 1.042299 | F48: =IF(ISBLANK(T48),"Stock Holding","SWAP Contract") -> Stock Holding | G48: =ISNUMBER(I48) -> TRUE | H48: BUY | I48: 0.1488 | J48: 45449.868 | K48: 67.2 | L48: 45481.658 | M48: 69.65 | N48: xStation Mobile iOS | O48: xStation Mobile iOS | P48: 10 | Q48: 10.36 | U48: 0 | V48: 0 | W48: 0 | X48: 0.36
...

Sheet OPEN POSITION
I5: Name and surname | L5: Account | O5: Currency | T5: 45793.063
I6: SAMUEL EDUARDO RODRIGUEZ WALTON | L6: 50704832 | O6: USD
I7: Balance | L7: Equity | O7: Margin | Q7: Free margin | T7: Margin level
I8: 85.05 | L8: 1605.25 | O8: 0 | Q8: 85.05 | T8: 0
B9: OPEN POSITION HISTORY
B10: 45793
B11: Position | C11: Symbol | D11: Chapter | E11: ToM | F11: InReport | G11: Type | H11: Volume | I11: Open time | J11: Open price | K11: Market price | L11: Purchase value | M11: SL | N11: TP | O11: Margin | P11: Commission | Q11: Swap | R11: Rollover | S11: Gross P/L | T11: Comment
B12: 1744916452 | C12: ING | D12: =IFERROR(INDEX([1]Positions!$A:$A,MATCH(C12,[1]Positions!$C:$C,0)),"Other") -> Financial Services | E12: =(NOW()-I12)/30.5 -> 1.3480436 | F12: =ISNUMBER(H12) -> TRUE | G12: BUY | H12: 0.4245 | I12: 45751.742 | J12: 17.54 | K12: 21.1 | L12: 7.45 | O12: 0 | P12: 0 | Q12: 0 | R12: 0 | S12: 1.51
B13: 1817264187 | C13: CIB | D13: =IFERROR(INDEX([1]Positions!$A:$A,MATCH(C13,[1]Positions!$C:$C,0)),"Other") -> Financial Services | E13: =(NOW()-I13)/30.5 -> 0.10521437 | F13: =ISNUMBER(H13) -> TRUE | G13: BUY | H13: 0.4757 | I13: 45789.649 | J13: 42.02 | K13: 42.15 | L13: 19.99 | O13: 0 | P13: 0 | Q13: 0 | R13: 0 | S13: 0.06
B14: 1566610015 | C14: APA | D14: =IFERROR(INDEX([1]Positions!$A:$A,MATCH(C14,[1]Positions!$C:$C,0)),"Other") -> Energy & Utilities | E14: =(NOW()-I14)/30.5 -> 5.2452774 | F14: =ISNUMBER(H14) -> TRUE | G14: BUY | H14: 0.9385 | I14: 45632.877 | J14: 21.31 | K14: 17.74 | L14: 20 | O14: 0 | P14: 0 | Q14: 0 | R14: 0 | S14: -3.35
B15: 1644796307 | C15: ACI | D15: =IFERROR(INDEX([1]Positions!$A:$A,MATCH(C15,[1]Positions!$C:$C,0)),"Other") -> Consumer Defensive | E15: =(NOW()-I15)/30.5 -> 3.2459874 | F15: =ISNUMBER(H15) -> TRUE | G15: BUY | H15: 1 | I15: 45693.855 | J15: 20.36 | K15: 21.9 | L15: 20.36 | O15: 0 | P15: 0 | Q15: 0 | R15: 0 | S15: 1.54
B16: 1582737192 | C16: MA | D16: =IFERROR(INDEX([1]Positions!$A:$A,MATCH(C16,[1]Positions!$C:$C,0)),"Other") -> Financial Services | E16: =(NOW()-I16)/30.5 -> 4.8182358 | F16: =ISNUMBER(H16) -> TRUE | G16: BUY | H16: 0.001 | I16: 45645.901 | J16: 524.43 | K16: 582.24 | L16: 0.52 | O16: 0 | P16: 0 | Q16: 0 | R16: 0 | S16: 0.06
B17: 1422773288 | C17: MO | D17: =IFERROR(INDEX([1]Positions!$A:$A,MATCH(C17,[1]Positions!$C:$C,0)),"Other") -> Consumer Defensive | E17: =(NOW()-I17)/30.5 -> 8.9840442 | F17: =ISNUMBER(H17) -> TRUE | G17: BUY | H17: 0.483 | I17: 45518.844 | J17: 51.24 | K17: 57.94 | L17: 24.75 | O17: 0 | P17: 0 | Q17: 0 | R17: 0 | S17: 3.24
B18: 1727563010 | C18: VWO | D18: =IFERROR(INDEX([1]Positions!$A:$A,MATCH(C18,[1]Positions!$C:$C,0)),"Other") -> ETF | E18: =(NOW()-I18)/30.5 -> 1.6097234 | F18: =ISNUMBER(H18) -> TRUE | G18: BUY | H18: 1 | I18: 45743.761 | J18: 46.11 | K18: 47.69 | L18: 46.11 | O18: 0 | P18: 0 | Q18: 0 | R18: 0 | S18: 1.58
B19: 1599455288 | C19: YPF | D19: =IFERROR(INDEX([1]Positions!$A:$A,MATCH(C19,[1]Positions!$C:$C,0)),"Other") -> Energy & Utilities | E19: =(NOW()-I19)/30.5 -> 4.2334469 | F19: =ISNUMBER(H19) -> TRUE | G19: BUY | H19: 0.2195 | I19: 45663.738 | J19: 45.55 | K19: 35.67 | L19: 10 | O19: 0 | P19: 0 | Q19: 0 | R19: 0 | S19: -2.17
B20: 1381417257 | C20: BATT.NL | D20: =IFERROR(INDEX([1]Positions!$A:$A,MATCH(C20,[1]Positions!$C:$C,0)),"Other") -> ETF | E20: =(NOW()-I20)/30.5 -> 10.104225 | F20: =ISNUMBER(H20) -> TRUE | G20: BUY | H20: 1 | I20: 45484.679 | J20: 16.374 | K20: 16.066 | L20: 17.9 | O20: 0 | P20: 0 | Q20: 0 | R20: 0 | S20: -0.03
B21: 1644789287 | C21: KMB | D21: =IFERROR(INDEX([1]Positions!$A:$A,MATCH(C21,[1]Positions!$C:$C,0)),"Other") -> Consumer Defensive | E21: =(NOW()-I21)/30.5 -> 3.2461115 | F21: =ISNUMBER(H21) -> TRUE | G21: BUY | H21: 0.0813 | I21: 45693.851 | J21: 129.08 | K21: 137.35 | L21: 10.49 | O21: 0 | P21: 0 | Q21: 0 | R21: 0 | S21: 0.68
B22: 1729617775 | C22: TSM | D22: =IFERROR(INDEX([1]Positions!$A:$A,MATCH(C22,[1]Positions!$C:$C,0)),"Other") -> Technology | E22: =(NOW()-I22)/30.5 -> 1.5784995 | F22: =ISNUMBER(H22) -> TRUE | G22: BUY | H22: 0.0907 | I22: 45744.713 | J22: 165.35 | K22: 194.23 | L22: 15 | O22: 0 | P22: 0 | Q22: 0 | R22: 0 | S22: 2.62
B23: 1554741910 | C23: ING | D23: =IFERROR(INDEX([1]Positions!$A:$A,MATCH(C23,[1]Positions!$C:$C,0)),"Other") -> Financial Services | E23: =(NOW()-I23)/30.5 -> 5.5445286 | F23: =ISNUMBER(H23) -> TRUE | G23: BUY | H23: 0.3495 | I23: 45623.75 | J23: 15.3 | K23: 21.1 | L23: 5.35 | O23: 0 | P23: 0 | Q23: 0 | R23: 0 | S23: 2.02
... B108: 1599435465 | C108: MA | D108: =IFERROR(INDEX([1]Positions!$A:$A,MATCH(C108,[1]Positions!$C:$C,0)),"Other") -> Financial Services | E108: =(NOW()-I108)/30.5 -> 4.233655 | F108: =ISNUMBER(H108) -> TRUE | G108: BUY | H108: 0.0289 | I108: 45663.731 | J108: 517.7 | K108: 582.24 | L108: 14.96 | O108: 0 | P108: 0 | Q108: 0 | R108: 0 | S108: 1.87
B109: Total | D109: =IFERROR(INDEX([1]Positions!$A:$A,MATCH(C109,[1]Positions!$C:$C,0)),"Other") -> Other | E109: =(NOW()-I109)/30.5 -> #VALUE! | F109: =ISNUMBER(H109) -> FALSE | P109: 0 | Q109: 0 | R109: 0 | S109: 64.76

Sheet PENDING ORDERS HISTORY 
D5: Name and surname | G5: Account | J5: Currency | M5: 45786.091
D6: SAMUEL EDUARDO RODRIGUEZ WALTON | G6: 50704832 | J6: USD
D7: Balance | G7: Equity | J7: Margin | L7: Free margin | M7: Margin level
D8: 93.01 | G8: 1531.79 | J8: 0 | L8: 93.01 | M8: 0
B9: PENDING ORDERS HISTORY
B10: 45786
B11: ID | C11: Symbol | D11: Purchase value | E11: Nominal Value | F11: Price | G11: Margin | H11: Type | I11: Order | J11: side | K11: SL | L11: TP | M11: Open time

Sheet CASH OPERATION HISTORY
D5: Name and surname | E5: Account | F5: Currency | K5: 45793.063
D6: SAMUEL EDUARDO RODRIGUEZ WALTON | E6: 50704832 | F6: USD
D7: Balance | E7: Equity | F7: Margin | J7: Free margin | K7: Margin level
D8: 85.05 | E8: 1605.25 | F8: 0 | J8: 85.05 | K8: 0
B9: CASH OPERATION HISTORY
B10: 01/01/2006 - 16/05/2025
B11: ID | C11: Type | D11: Time | E11: Comment | F11: Symbol | G11: Chapter | H11: InReport | I11: DATE | J11: Amount
B12: 807882095 | C12: Stock purchase | D12: 45789.648 | E12: OPEN BUY 0.2267 @ 44.10 | F12: EXC | G12: =IFERROR(INDEX([1]Positions!$A:$A,MATCH(F12,[1]Positions!$C:$C,0)),"Other") -> Energy & Utilities | H12: =ISNUMBER(D12) -> TRUE | I12: =TEXT(D12,"YYYY-MM-DD") -> 2025-05-12 | J12: -10
B13: 743536649 | C13: close trade | D13: 45726.375 | E13: Profit of position #1393281432 | F13: FLOA.UK | G13: =IFERROR(INDEX([1]Positions!$A:$A,MATCH(F13,[1]Positions!$C:$C,0)),"Other") -> MISC | H13: =ISNUMBER(D13) -> TRUE | I13: =TEXT(D13,"YYYY-MM-DD") -> 2025-03-10 | J13: 0.21
B14: 743536650 | C14: Stock sale | D14: 45726.375 | E14: CLOSE BUY 1/1.6706 @ 6.1860 | F14: FLOA.UK | G14: =IFERROR(INDEX([1]Positions!$A:$A,MATCH(F14,[1]Positions!$C:$C,0)),"Other") -> MISC | H14: =ISNUMBER(D14) -> TRUE | I14: =TEXT(D14,"YYYY-MM-DD") -> 2025-03-10 | J14: 5.98
B15: 743538255 | C15: close trade | D15: 45726.375 | E15: Profit of position #1393281260 | F15: SDIA.UK | G15: =IFERROR(INDEX([1]Positions!$A:$A,MATCH(F15,[1]Positions!$C:$C,0)),"Other") -> MISC | H15: =ISNUMBER(D15) -> TRUE | I15: =TEXT(D15,"YYYY-MM-DD") -> 2025-03-10 | J15: 0.3
B16: 743538256 | C16: Stock sale | D16: 45726.375 | E16: CLOSE BUY 1.4632/2.9908 @ 6.0200 | F16: SDIA.UK | G16: =IFERROR(INDEX([1]Positions!$A:$A,MATCH(F16,[1]Positions!$C:$C,0)),"Other") -> MISC | H16: =ISNUMBER(D16) -> TRUE | I16: =TEXT(D16,"YYYY-MM-DD") -> 2025-03-10 | J16: 8.51
B17: 743538257 | C17: close trade | D17: 45726.375 | E17: Profit of position #1393287040 | F17: SDIA.UK | G17: =IFERROR(INDEX([1]Positions!$A:$A,MATCH(F17,[1]Positions!$C:$C,0)),"Other") -> MISC | H17: =ISNUMBER(D17) -> TRUE | I17: =TEXT(D17,"YYYY-MM-DD") -> 2025-03-10 | J17: 0.06
B18: 743538259 | C18: Stock sale | D18: 45726.375 | E18: CLOSE BUY 0.2503/2.9908 @ 6.0200 | F18: SDIA.UK | G18: =IFERROR(INDEX([1]Positions!$A:$A,MATCH(F18,[1]Positions!$C:$C,0)),"Other") -> MISC | H18: =ISNUMBER(D18) -> TRUE | I18: =TEXT(D18,"YYYY-MM-DD") -> 2025-03-10 | J18: 1.45
B19: 743538262 | C19: close trade | D19: 45726.375 | E19: Profit of position #1403180431 | F19: SDIA.UK | G19: =IFERROR(INDEX([1]Positions!$A:$A,MATCH(F19,[1]Positions!$C:$C,0)),"Other") -> MISC | H19: =ISNUMBER(D19) -> TRUE | I19: =TEXT(D19,"YYYY-MM-DD") -> 2025-03-10 | J19: 0.05
B20: 743538263 | C20: Stock sale | D20: 45726.375 | E20: CLOSE BUY 0.2773/2.9908 @ 6.0200 | F20: SDIA.UK | G20: =IFERROR(INDEX([1]Positions!$A:$A,MATCH(F20,[1]Positions!$C:$C,0)),"Other") -> MISC | H20: =ISNUMBER(D20) -> TRUE | I20: =TEXT(D20,"YYYY-MM-DD") -> 2025-03-10 | J20: 1.62
B21: 743538266 | C21: close trade | D21: 45726.375 | E21: Profit of position #1403180445 | F21: SDIA.UK | G21: =IFERROR(INDEX([1]Positions!$A:$A,MATCH(F21,[1]Positions!$C:$C,0)),"Other") -> MISC | H21: =ISNUMBER(D21) -> TRUE | I21: =TEXT(D21,"YYYY-MM-DD") -> 2025-03-10 | J21: 0.01
B22: 743538267 | C22: Stock sale | D22: 45726.375 | E22: CLOSE BUY 0.0092/2.9908 @ 6.0200 | F22: SDIA.UK | G22: =IFERROR(INDEX([1]Positions!$A:$A,MATCH(F22,[1]Positions!$C:$C,0)),"Other") -> MISC | H22: =ISNUMBER(D22) -> TRUE | I22: =TEXT(D22,"YYYY-MM-DD") -> 2025-03-10 | J22: 0.05
B23: 743548157 | C23: close trade | D23: 45726.376 | E23: Profit of position #1393735509 | F23: VHYD.UK | G23: =IFERROR(INDEX([1]Positions!$A:$A,MATCH(F23,[1]Positions!$C:$C,0)),"Other") -> MISC | H23: =ISNUMBER(D23) -> TRUE | I23: =TEXT(D23,"YYYY-MM-DD") -> 2025-03-10 | J23: 0.13
... B39: 745059933 | C39: Stock sale | D39: 45727.386 | E39: CLOSE BUY 0.4203/0.6706 @ 6.1760 | F39: FLOA.UK | G39: =IFERROR(INDEX([1]Positions!$A:$A,MATCH(F39,[1]Positions!$C:$C,0)),"Other") -> MISC | H39: =ISNUMBER(D39) -> TRUE | I39: =TEXT(D39,"YYYY-MM-DD") -> 2025-03-11 | J39: 2.52
B40: 745059994 | C40: Subaccount Transfer | D40: 45727.386 | E40: Transfer from 50872299 to 50704832 | G40: =IFERROR(INDEX([1]Positions!$A:$A,MATCH(F40,[1]Positions!$C:$C,0)),"Other") -> Other | H40: =ISNUMBER(D40) -> TRUE | I40: =TEXT(D40,"YYYY-MM-DD") -> 2025-03-11 | J40: -52.08
B41: 745059928 | C41: close trade | D41: 45727.386 | E41: Profit of position #1393281432 | F41: FLOA.UK | G41: =IFERROR(INDEX([1]Positions!$A:$A,MATCH(F41,[1]Positions!$C:$C,0)),"Other") -> MISC | H41: =ISNUMBER(D41) -> TRUE | I41: =TEXT(D41,"YYYY-MM-DD") -> 2025-03-11 | J41: 0.02
B42: 584485943 | C42: Subaccount Transfer | D42: 45495.926 | E42: Transfer from 50704832 to 50872299 | G42: =IFERROR(INDEX([1]Positions!$A:$A,MATCH(F42,[1]Positions!$C:$C,0)),"Other") -> Other | H42: =ISNUMBER(D42) -> TRUE | I42: =TEXT(D42,"YYYY-MM-DD") -> 2024-07-22 | J42: 50
B43: 584584545 | C43: Stock purchase | D43: 45496.376 | E43: OPEN BUY 4/4.1401 @ 5.9810 | F43: FLOA.UK | G43: =IFERROR(INDEX([1]Positions!$A:$A,MATCH(F43,[1]Positions!$C:$C,0)),"Other") -> MISC | H43: =ISNUMBER(D43) -> TRUE | I43: =TEXT(D43,"YYYY-MM-DD") -> 2024-07-23 | J43: -23.92
B44: 584584380 | C44: Stock purchase | D44: 45496.376 | E44: OPEN BUY 4/4.2503 @ 5.8120 | F44: SDIA.UK | G44: =IFERROR(INDEX([1]Positions!$A:$A,MATCH(F44,[1]Positions!$C:$C,0)),"Other") -> MISC | H44: =ISNUMBER(D44) -> TRUE | I44: =TEXT(D44,"YYYY-MM-DD") -> 2024-07-23 | J44: -23.25
B45: 584587915 | C45: Stock purchase | D45: 45496.378 | E45: OPEN BUY 0.2503/4.2503 @ 5.8110 | F45: SDIA.UK | G45: =IFERROR(INDEX([1]Positions!$A:$A,MATCH(F45,[1]Positions!$C:$C,0)),"Other") -> MISC | H45: =ISNUMBER(D45) -> TRUE | I45: =TEXT(D45,"YYYY-MM-DD") -> 2024-07-23 | J45: -1.45
B46: 584598125 | C46: Stock purchase | D46: 45496.379 | E46: OPEN BUY 0.1401/4.1401 @ 5.9900 | F46: FLOA.UK | G46: =IFERROR(INDEX([1]Positions!$A:$A,MATCH(F46,[1]Positions!$C:$C,0)),"Other") -> MISC | H46: =ISNUMBER(D46) -> TRUE | I46: =TEXT(D46,"YYYY-MM-DD") -> 2024-07-23 | J46: -0.84
B47: 584801661 | C47: Stock purchase | D47: 45496.618 | E47: OPEN BUY 0.0366 @ 67.370 | F47: VHYD.UK | G47: =IFERROR(INDEX([1]Positions!$A:$A,MATCH(F47,[1]Positions!$C:$C,0)),"Other") -> MISC | H47: =ISNUMBER(D47) -> TRUE | I47: =TEXT(D47,"YYYY-MM-DD") -> 2024-07-23 | J47: -2.47
B48: 584801647 | C48: close trade | D48: 45496.618 | E48: Profit of position #1393281260 | F48: SDIA.UK | G48: =IFERROR(INDEX([1]Positions!$A:$A,MATCH(F48,[1]Positions!$C:$C,0)),"Other") -> MISC | H48: =ISNUMBER(D48) -> TRUE | I48: =TEXT(D48,"YYYY-MM-DD") -> 2024-07-23 | J48: 0
B49: 584801648 | C49: Stock sale | D49: 45496.618 | E49: CLOSE BUY 0.5612 @ 5.8100 | F49: SDIA.UK | G49: =IFERROR(INDEX([1]Positions!$A:$A,MATCH(F49,[1]Positions!$C:$C,0)),"Other") -> MISC | H49: =ISNUMBER(D49) -> TRUE | I49: =TEXT(D49,"YYYY-MM-DD") -> 2024-07-23 | J49: 3.26
B50: 584801643 | C50: close trade | D50: 45496.618 | E50: Profit of position #1393281432 | F50: FLOA.UK | G50: =IFERROR(INDEX([1]Positions!$A:$A,MATCH(F50,[1]Positions!$C:$C,0)),"Other") -> MISC | H50: =ISNUMBER(D50) -> TRUE | I50: =TEXT(D50,"YYYY-MM-DD") -> 2024-07-23 | J50: -0.01
B51: 584801644 | C51: Stock sale | D51: 45496.618 | E51: CLOSE BUY 0.632 @ 5.9670 | F51: FLOA.UK | G51: =IFERROR(INDEX([1]Positions!$A:$A,MATCH(F51,[1]Positions!$C:$C,0)),"Other") -> MISC | H51: =ISNUMBER(D51) -> TRUE | I51: =TEXT(D51,"YYYY-MM-DD") -> 2024-07-23 | J51: 3.78
B52: 585465634 | C52: Stock purchase | D52: 45497.654 | E52: OPEN BUY 0.074 @ 67.130 | F52: VHYD.UK | G52: =IFERROR(INDEX([1]Positions!$A:$A,MATCH(F52,[1]Positions!$C:$C,0)),"Other") -> MISC | H52: =ISNUMBER(D52) -> TRUE | I52: =TEXT(D52,"YYYY-MM-DD") -> 2024-07-24 | J52: -4.97
B53: 585465630 | C53: close trade | D53: 45497.654 | E53: Profit of position #1393281260 | F53: SDIA.UK | G53: =IFERROR(INDEX([1]Positions!$A:$A,MATCH(F53,[1]Positions!$C:$C,0)),"Other") -> MISC | H53: =ISNUMBER(D53) -> TRUE | I53: =TEXT(D53,"YYYY-MM-DD") -> 2024-07-24 | J53: -0.01
B54: 585465631 | C54: Stock sale | D54: 45497.654 | E54: CLOSE BUY 0.555/1.555 @ 5.8010 | F54: SDIA.UK | G54: =IFERROR(INDEX([1]Positions!$A:$A,MATCH(F54,[1]Positions!$C:$C,0)),"Other") -> MISC | H54: =ISNUMBER(D54) -> TRUE | I54: =TEXT(D54,"YYYY-MM-DD") -> 2024-07-24 | J54: 3.23
... B91: 747747258 | C91: Withholding Tax | D91: 45729.498 | E91: MSFT.US USD WHT 30% | F91: MSFT | G91: =IFERROR(INDEX([1]Positions!$A:$A,MATCH(F91,[1]Positions!$C:$C,0)),"Other") -> Technology | H91: =ISNUMBER(D91) -> TRUE | I91: =TEXT(D91,"YYYY-MM-DD") -> 2025-03-13 | J91: -0.01
B92: 735126956 | C92: deposit | D92: 45716.85 | E92: SafetyPay deposit, SafetyPay provider transaction id=0125059444032332, SafetyPay merchant reference id=249604, id=17602808 | G92: =IFERROR(INDEX([1]Positions!$A:$A,MATCH(F92,[1]Positions!$C:$C,0)),"Other") -> Other | H92: =ISNUMBER(D92) -> TRUE | I92: =TEXT(D92,"YYYY-MM-DD") -> 2025-02-28 | J92: 85
B93: 686269321 | C93: DIVIDENT | D93: 45653.524 | E93: VHYD.UK USD 0.4296/ SHR | F93: VHYD.UK | G93: =IFERROR(INDEX([1]Positions!$A:$A,MATCH(F93,[1]Positions!$C:$C,0)),"Other") -> MISC | H93: =ISNUMBER(D93) -> TRUE | I93: =TEXT(D93,"YYYY-MM-DD") -> 2024-12-27 | J93: 0.03
B94: 735131727 | C94: Stock purchase | D94: 45716.856 | E94: OPEN BUY 0.1958 @ 178.67 | F94: TSM | G94: =IFERROR(INDEX([1]Positions!$A:$A,MATCH(F94,[1]Positions!$C:$C,0)),"Other") -> Technology | H94: =ISNUMBER(D94) -> TRUE | I94: =TEXT(D94,"YYYY-MM-DD") -> 2025-02-28 | J94: -34.98
B95: 735132884 | C95: Stock purchase | D95: 45716.857 | E95: OPEN BUY 0.7278 @ 20.60 | F95: APA | G95: =IFERROR(INDEX([1]Positions!$A:$A,MATCH(F95,[1]Positions!$C:$C,0)),"Other") -> Energy & Utilities | H95: =ISNUMBER(D95) -> TRUE | I95: =TEXT(D95,"YYYY-MM-DD") -> 2025-02-28 | J95: -14.99
...

Sheet CLOSED POSITION HISTORY MT
H5: Name and surname | K5: Account | N5: Currency | W5: 45786.091
H6: SAMUEL EDUARDO RODRIGUEZ WALTON | K6: 50704832 | N6: USD
H7: Balance | K7: Equity | N7: Margin | Q7: Free margin | T7: Margin level
H8: 93.01 | K8: 1531.79 | N8: 0 | Q8: 93.01 | T8: 0
B9: CLOSED POSITION HISTORY MT
B10: 01/01/2006 - 09/05/2025
B12: Position | D12: Symbol | F12: Type | G12: Volume | H12: Open time | I12: Open price | J12: Close time | K12: Close price | L12: Commission | M12: Swap | N12: Gross P/L | O12: Comment
B13: 561654650 | D13: SHELL.NL | F13: Closed | G13: 0.4139 | H13: 45446.375 | I13: 33.545 | J13: 45453.664 | K13: 32.605 | L13: 0 | M13: 0 | N13: -0.73 | O13: ""
B14: 561850164 | D14: US.30 | F14: Closed | G14: 0.01 | H14: 45453.906 | I14: 38900 | J14: 45453.91 | K14: 38869 | L14: 0 | M14: 0 | N14: -1.55 | O14: ""
B15: 565713106 | D15: PEP | F15: Closed | G15: 0.123 | H15: 45460.646 | I15: 1.65 | J15: 45460.738 | K15: 165.24 | L15: 0 | M15: 0 | N15: 0 | O15: ""
B16: 565713108 | D16: PEP | F16: Closed | G16: 0 | H16: 45460.646 | I16: 1.65 | J16: 45460 | K16: 165.24 | L16: 0 | M16: 0 | N16: 0 | O16: ""
B17: 565825453 | D17: SMFG | F17: Closed | G17: 1 | H17: 45446.904 | I17: 13.37 | J17: 45460.885 | K17: 12.62 | L17: 0 | M17: 0 | N17: -0.75 | O17: ""
B18: 568018581 | D18: NVDA | F18: Closed | G18: 0.12 | H18: 45452.644 | I18: 118.42 | J18: 45464.646 | K18: 126.75 | L18: 0 | M18: 0 | N18: 1 | O18: Transfer In
B19: 568018754 | D19: QCOM | F19: Closed | G19: 0.0975 | H19: 45446.894 | I19: 205.08 | J19: 45464.646 | K19: 211.24 | L19: 0 | M19: 0 | N19: 0.6 | O19: ""
B20: 568018921 | D20: NVDA | F20: Closed | G20: 0.051 | H20: 45452.644 | I20: 118.42 | J20: 45464.646 | K20: 126.76 | L20: 0 | M20: 0 | N20: 0.42 | O20: Transfer In
B21: 568057989 | D21: AVGO | F21: Closed | G21: 0.0115 | H21: 45460.686 | I21: 1797.13 | J21: 45464.66 | K21: 1686.26 | L21: 0 | M21: 0 | N21: -1.28 | O21: ""
B22: 568079573 | D22: GILD | F22: Closed | G22: 0.2806 | H22: 45464.662 | I22: 71.61 | J22: 45464.667 | K22: 70.96 | L22: 0 | M22: 0 | N22: -0.18 | O22: ""
B23: 575788975 | D23: TSM | F23: Closed | G23: 0.1322 | H23: 45446.646 | I23: 155.59 | J23: 45478.652 | K23: 183.6 | L23: 0 | M23: 0 | N23: 3.7 | O23: ""
B24: 576566234 | D24: WMT | F24: Closed | G24: 0.1488 | H24: 45449.868 | I24: 67.2 | J24: 45481.658 | K24: 69.65 | L24: 0 | M24: 0 | N24: 0.36 | O24: ""
... B131: 803547672 | D131: MSFT | F131: Closed | G131: 0.0372 | H131: 45523.666 | I131: 419.46 | J131: 45784.777 | K131: 434.71 | L131: 0 | M131: 0 | N131: 0.56 | O131: ""
B132: Total | L132: 0 | M132: -2.32 | N132: 9.58

Sheet BALANCE OPERATION HISTORY MT
D5: Name and surname | E5: Account | F5: Currency | H5: 45786.091
D6: SAMUEL EDUARDO RODRIGUEZ WALTON | E6: 50704832 | F6: USD
D7: Balance | E7: Equity | F7: Margin | G7: Free margin | H7: Margin level
D8: 93.01 | E8: 1531.79 | F8: 0 | G8: 93.01 | H8: 0
B9: BALANCE OPERATION HISTORY MT
B10: 01/01/2006 - 09/05/2025
B11: ID | C11: Type | D11: Time | E11: Comment | F11: Amount
B12: 576516261 | C12: Deposit | D12: 45443 | E12: ECOMMPAY card deposit, ECOMMPAY provider transaction id=1717160381025_178431418,ECOMMPAY merchant re | F12: 100
B13: 577153112 | C13: Withdraw | D13: 45446 | E13: OPEN BUY 0.4139 @ 33.545 | F13: -15.15
B14: 577470756 | C14: Withdraw | D14: 45446 | E14: OPEN BUY 0.1322 @ 155.59 | F14: -20.57
B15: 577778020 | C15: Withdraw | D15: 45446 | E15: OPEN BUY 0.0975 @ 205.08 | F15: -20
B16: 577784122 | C16: Withdraw | D16: 45446 | E16: OPEN BUY 1 @ 13.37 | F16: -13.37
B17: 579538038 | C17: Withdraw | D17: 45448 | E17: OPEN BUY 0.0171 @ 1184.19 | F17: -20.25
B18: 580399287 | C18: Withdraw | D18: 45449 | E18: OPEN BUY 0.1488 @ 67.20 | F18: -10
B19: 581654651 | C19: Deposit | D19: 45453 | E19: CLOSE BUY 0.4139 @ 32.605 | F19: 15.15
B20: 581852140 | C20: Withdraw | D20: 45453 | E20: OPEN BUY 0.0234 @ 427.17 | F20: -10
B21: 584919536 | C21: Deposit | D21: 45458 | E21: ECOMMPAY card deposit, ECOMMPAY provider transaction id=1718411934936_-192576474,ECOMMPAY merchant r | F21: 50
B22: 585607855 | C22: Withdraw | D22: 45460 | E22: OPEN BUY 0.123 @ 1.65 | F22: -0.2
B23: 585611180 | C23: Withdraw | D23: 45460 | E23: OPEN BUY 1 @ 22.89 | F23: -22.89
... B467: 823547673 | C467: Deposit | D467: 45784 | E467: CLOSE BUY 0.0372/0.0606 @ 434.71 | F467: 15.61
B468: Total | F468: 68.27
